2024-08-24 15:21:26|ERROR|app.py:35|module 'Error' has no attribute 'ErrResult'
Traceback (most recent call last):
  File "app.py", line 32, in wrapper
    return func(*args,**kwargs)
  File "app.py", line 64, in POST
    return Error.ErrResult(ErrorCfg.EC_REGISTER_PWD_TYPE_ERROR,ErrorCfg.ER_REGISTER_PWD_TYPE_ERROR)
AttributeError: module 'Error' has no attribute 'ErrResult'
2024-08-24 15:22:23|ERROR|app.py:35|module 'Error' has no attribute 'ErrResult'
Traceback (most recent call last):
  File "app.py", line 32, in wrapper
    return func(*args,**kwargs)
  File "app.py", line 64, in POST
    return Error.ErrResult(ErrorCfg.EC_REGISTER_PWD_TYPE_ERROR,ErrorCfg.ER_REGISTER_PWD_TYPE_ERROR)
AttributeError: module 'Error' has no attribute 'ErrResult'
2024-08-24 15:24:49|ERROR|app.py:35|module 'Account' has no attribute 'checkPassword'
Traceback (most recent call last):
  File "app.py", line 32, in wrapper
    return func(*args,**kwargs)
  File "app.py", line 63, in POST
    if not Account.checkPassword(password):
AttributeError: module 'Account' has no attribute 'checkPassword'
2024-08-24 15:44:55|ERROR|app.py:35|module 'Account' has no attribute 'InitUser'
Traceback (most recent call last):
  File "app.py", line 32, in wrapper
    return func(*args,**kwargs)
  File "app.py", line 69, in POST
    Account.InitUser(phoneNum, password, nick, sex, idCard)
AttributeError: module 'Account' has no attribute 'InitUser'
2024-08-24 15:45:44|ERROR|app.py:35|module 'Account' has no attribute 'InitUser'
Traceback (most recent call last):
  File "app.py", line 32, in wrapper
    return func(*args,**kwargs)
  File "app.py", line 69, in POST
    Account.initUser(phoneNum, password, nick, sex, idCard)
AttributeError: module 'Account' has no attribute 'InitUser'
2024-08-24 15:45:58|ERROR|app.py:35|(1054, "Unknown column 'porp_1001' in 'field list'")
Traceback (most recent call last):
  File "app.py", line 32, in wrapper
    return func(*args,**kwargs)
  File "app.py", line 69, in POST
    Account.initUser(phoneNum, password, nick, sex, idCard)
  File "/home/weihong/backendFrame/webpy/./Account.py", line 116, in initUser
    DBManage.initPackage(packageInfo)
  File "/home/weihong/backendFrame/webpy/./DBManage.py", line 34, in initPackage
    result = Config.gdb.insert(
  File "/usr/local/lib/python3.10/dist-packages/web/db.py", line 1008, in insert
    self._db_execute(db_cursor, q1)
  File "/usr/local/lib/python3.10/dist-packages/web/db.py", line 764, in _db_execute
    out = cur.execute(query, params)
  File "/usr/local/lib/python3.10/dist-packages/pymysql/cursors.py", line 153, in execute
    result = self._query(query)
  File "/usr/local/lib/python3.10/dist-packages/pymysql/cursors.py", line 322, in _query
    conn.query(q)
  File "/usr/local/lib/python3.10/dist-packages/pymysql/connections.py", line 563, in query
    self._affected_rows = self._read_query_result(unbuffered=unbuffered)
  File "/usr/local/lib/python3.10/dist-packages/pymysql/connections.py", line 825, in _read_query_result
    result.read()
  File "/usr/local/lib/python3.10/dist-packages/pymysql/connections.py", line 1199, in read
    first_packet = self.connection._read_packet()
  File "/usr/local/lib/python3.10/dist-packages/pymysql/connections.py", line 775, in _read_packet
    packet.raise_for_error()
  File "/usr/local/lib/python3.10/dist-packages/pymysql/protocol.py", line 219, in raise_for_error
    err.raise_mysql_exception(self._data)
  File "/usr/local/lib/python3.10/dist-packages/pymysql/err.py", line 150, in raise_mysql_exception
    raise errorclass(errno, errval)
pymysql.err.OperationalError: (1054, "Unknown column 'porp_1001' in 'field list'")
2024-08-24 15:49:05|ERROR|app.py:35|(1054, "Unknown column 'prop_1006' in 'field list'")
Traceback (most recent call last):
  File "app.py", line 32, in wrapper
    return func(*args,**kwargs)
  File "app.py", line 69, in POST
    Account.initUser(phoneNum, password, nick, sex, idCard)
  File "/home/weihong/backendFrame/webpy/./Account.py", line 116, in initUser
    DBManage.initPackage(packageInfo)
  File "/home/weihong/backendFrame/webpy/./DBManage.py", line 34, in initPackage
    result = Config.gdb.insert(
  File "/usr/local/lib/python3.10/dist-packages/web/db.py", line 1008, in insert
    self._db_execute(db_cursor, q1)
  File "/usr/local/lib/python3.10/dist-packages/web/db.py", line 764, in _db_execute
    out = cur.execute(query, params)
  File "/usr/local/lib/python3.10/dist-packages/pymysql/cursors.py", line 153, in execute
    result = self._query(query)
  File "/usr/local/lib/python3.10/dist-packages/pymysql/cursors.py", line 322, in _query
    conn.query(q)
  File "/usr/local/lib/python3.10/dist-packages/pymysql/connections.py", line 563, in query
    self._affected_rows = self._read_query_result(unbuffered=unbuffered)
  File "/usr/local/lib/python3.10/dist-packages/pymysql/connections.py", line 825, in _read_query_result
    result.read()
  File "/usr/local/lib/python3.10/dist-packages/pymysql/connections.py", line 1199, in read
    first_packet = self.connection._read_packet()
  File "/usr/local/lib/python3.10/dist-packages/pymysql/connections.py", line 775, in _read_packet
    packet.raise_for_error()
  File "/usr/local/lib/python3.10/dist-packages/pymysql/protocol.py", line 219, in raise_for_error
    err.raise_mysql_exception(self._data)
  File "/usr/local/lib/python3.10/dist-packages/pymysql/err.py", line 150, in raise_mysql_exception
    raise errorclass(errno, errval)
pymysql.err.OperationalError: (1054, "Unknown column 'prop_1006' in 'field list'")
2024-08-24 17:10:12|ERROR|app.py:35|handleLogin() missing 1 required positional argument: 'session'
Traceback (most recent call last):
  File "app.py", line 32, in wrapper
    # 获取记录器
  File "app.py", line 85, in POST
TypeError: handleLogin() missing 1 required positional argument: 'session'
2024-08-24 17:54:39|ERROR|app.py:43|already passed 0
Traceback (most recent call last):
  File "app.py", line 40, in wrapper
    return func(*args,**kwargs)
  File "app.py", line 99, in POST
    result = Account.verifyAccount(userId,password)
  File "/home/weihong/backendFrame/webpy/./Account.py", line 133, in verifyAccount
    print("Account verifyAccount result[0]['password']  {}".format(result[0]['password']))
  File "/usr/local/lib/python3.10/dist-packages/web/db.py", line 531, in __getitem__
    raise IndexError("already passed " + str(i))
IndexError: already passed 0
2024-08-24 17:59:50|ERROR|app.py:43|already passed 0
Traceback (most recent call last):
  File "app.py", line 40, in wrapper
    return func(*args,**kwargs)
  File "app.py", line 99, in POST
    result = Account.verifyAccount(userId,password)
  File "/home/weihong/backendFrame/webpy/./Account.py", line 129, in verifyAccount
    if result[0]['password'] != password:
  File "/usr/local/lib/python3.10/dist-packages/web/db.py", line 531, in __getitem__
    raise IndexError("already passed " + str(i))
IndexError: already passed 0
2024-08-24 18:08:16|ERROR|app.py:43|0
Traceback (most recent call last):
  File "/usr/local/lib/python3.10/dist-packages/web/db.py", line 538, in __getitem__
    return next(self)
  File "/usr/local/lib/python3.10/dist-packages/web/db.py", line 510, in __next__
    raise StopIteration()
StopIteration

During handling of the above exception, another exception occurred:

Traceback (most recent call last):
  File "app.py", line 40, in wrapper
    return func(*args,**kwargs)
  File "app.py", line 99, in POST
    result = Account.verifyAccount(userId,password)
  File "/home/weihong/backendFrame/webpy/./Account.py", line 126, in verifyAccount
    if result[0]['userid'] != userId:
  File "/usr/local/lib/python3.10/dist-packages/web/db.py", line 540, in __getitem__
    raise IndexError(str(i))
IndexError: 0
2024-08-24 18:19:41|ERROR|app.py:43|SQLQuery.__init__() takes from 1 to 2 positional arguments but 3 were given
Traceback (most recent call last):
  File "app.py", line 40, in wrapper
    return func(*args,**kwargs)
  File "app.py", line 99, in POST
    result = Account.verifyAccount(userId,password)
  File "/home/weihong/backendFrame/webpy/./Account.py", line 122, in verifyAccount
    result = Config.gdb.select("user", what=['password', 'status'], where="userid=$userid", vars=dict(userid=userId))
  File "/usr/local/lib/python3.10/dist-packages/web/db.py", line 880, in select
    clauses = [
  File "/usr/local/lib/python3.10/dist-packages/web/db.py", line 881, in <listcomp>
    self.gen_clause(sql, val, vars)
  File "/usr/local/lib/python3.10/dist-packages/web/db.py", line 948, in gen_clause
    nout = SQLQuery(val[0], val[1])  # backwards-compatibility
TypeError: SQLQuery.__init__() takes from 1 to 2 positional arguments but 3 were given
2024-08-24 18:25:50|ERROR|app.py:43|already passed 0
Traceback (most recent call last):
  File "app.py", line 40, in wrapper
    return func(*args,**kwargs)
  File "app.py", line 99, in POST
    result = Account.verifyAccount(userId,password)
  File "/home/weihong/backendFrame/webpy/./Account.py", line 129, in verifyAccount
    user_password, user_status = result[0]['password'], result[0]['status']
  File "/usr/local/lib/python3.10/dist-packages/web/db.py", line 531, in __getitem__
    raise IndexError("already passed " + str(i))
IndexError: already passed 0
2024-08-24 18:26:25|ERROR|app.py:43|already passed 0
Traceback (most recent call last):
  File "app.py", line 40, in wrapper
    return func(*args,**kwargs)
  File "app.py", line 99, in POST
    result = Account.verifyAccount(userId,password)
  File "/home/weihong/backendFrame/webpy/./Account.py", line 129, in verifyAccount
    user_password, user_status = result[0]['password'], result[0]['status']
  File "/usr/local/lib/python3.10/dist-packages/web/db.py", line 531, in __getitem__
    raise IndexError("already passed " + str(i))
IndexError: already passed 0
2024-08-24 18:26:37|ERROR|app.py:43|already passed 0
Traceback (most recent call last):
  File "app.py", line 40, in wrapper
    return func(*args,**kwargs)
  File "app.py", line 99, in POST
    result = Account.verifyAccount(userId,password)
  File "/home/weihong/backendFrame/webpy/./Account.py", line 129, in verifyAccount
    user_password, user_status = result[0]['password'], result[0]['status']
  File "/usr/local/lib/python3.10/dist-packages/web/db.py", line 531, in __getitem__
    raise IndexError("already passed " + str(i))
IndexError: already passed 0
2024-08-24 18:27:01|ERROR|app.py:43|SQLQuery.__init__() takes from 1 to 2 positional arguments but 3 were given
Traceback (most recent call last):
  File "app.py", line 40, in wrapper
    return func(*args,**kwargs)
  File "app.py", line 99, in POST
    result = Account.verifyAccount(userId,password)
  File "/home/weihong/backendFrame/webpy/./Account.py", line 122, in verifyAccount
    result = Config.gdb.select("user", what=['password', 'status'], where="userid=$userid", vars=dict(userid=userId))
  File "/usr/local/lib/python3.10/dist-packages/web/db.py", line 880, in select
    clauses = [
  File "/usr/local/lib/python3.10/dist-packages/web/db.py", line 881, in <listcomp>
    self.gen_clause(sql, val, vars)
  File "/usr/local/lib/python3.10/dist-packages/web/db.py", line 948, in gen_clause
    nout = SQLQuery(val[0], val[1])  # backwards-compatibility
TypeError: SQLQuery.__init__() takes from 1 to 2 positional arguments but 3 were given
2024-08-24 18:30:19|ERROR|app.py:43|SQLQuery.__init__() takes from 1 to 2 positional arguments but 3 were given
Traceback (most recent call last):
  File "app.py", line 40, in wrapper
    return func(*args,**kwargs)
  File "app.py", line 99, in POST
    result = Account.verifyAccount(userId,password)
  File "/home/weihong/backendFrame/webpy/./Account.py", line 122, in verifyAccount
    result = Config.gdb.select("user", what=['password', 'status'], where="userid=$userid", vars=dict(userid=userId))
  File "/usr/local/lib/python3.10/dist-packages/web/db.py", line 880, in select
    clauses = [
  File "/usr/local/lib/python3.10/dist-packages/web/db.py", line 881, in <listcomp>
    self.gen_clause(sql, val, vars)
  File "/usr/local/lib/python3.10/dist-packages/web/db.py", line 948, in gen_clause
    nout = SQLQuery(val[0], val[1])  # backwards-compatibility
TypeError: SQLQuery.__init__() takes from 1 to 2 positional arguments but 3 were given
2024-08-24 18:33:38|ERROR|app.py:43|SQLQuery.__init__() takes from 1 to 2 positional arguments but 3 were given
Traceback (most recent call last):
  File "app.py", line 40, in wrapper
    return func(*args,**kwargs)
  File "app.py", line 99, in POST
    result = Account.verifyAccount(userId,password)
  File "/home/weihong/backendFrame/webpy/./Account.py", line 122, in verifyAccount
    # 按照账号直接取出密码，后面可以直接按照密码进行校验，可以少一次数据库查找
  File "/usr/local/lib/python3.10/dist-packages/web/db.py", line 880, in select
    clauses = [
  File "/usr/local/lib/python3.10/dist-packages/web/db.py", line 881, in <listcomp>
    self.gen_clause(sql, val, vars)
  File "/usr/local/lib/python3.10/dist-packages/web/db.py", line 948, in gen_clause
    nout = SQLQuery(val[0], val[1])  # backwards-compatibility
TypeError: SQLQuery.__init__() takes from 1 to 2 positional arguments but 3 were given
2024-08-24 18:33:48|ERROR|app.py:43|already passed 0
Traceback (most recent call last):
  File "app.py", line 40, in wrapper
    return func(*args,**kwargs)
  File "app.py", line 99, in POST
    result = Account.verifyAccount(userId,password)
  File "/home/weihong/backendFrame/webpy/./Account.py", line 129, in verifyAccount
    if result[0]['password'] != password:
  File "/usr/local/lib/python3.10/dist-packages/web/db.py", line 531, in __getitem__
    raise IndexError("already passed " + str(i))
IndexError: already passed 0
2024-08-24 18:34:41|ERROR|app.py:43|already passed 0
Traceback (most recent call last):
  File "app.py", line 40, in wrapper
    return func(*args,**kwargs)
  File "app.py", line 99, in POST
    result = Account.verifyAccount(userId,password)
  File "/home/weihong/backendFrame/webpy/./Account.py", line 129, in verifyAccount
    if result[0]['password'] != password:
  File "/usr/local/lib/python3.10/dist-packages/web/db.py", line 531, in __getitem__
    raise IndexError("already passed " + str(i))
IndexError: already passed 0
2024-08-24 18:34:54|ERROR|app.py:43|0
Traceback (most recent call last):
  File "/usr/local/lib/python3.10/dist-packages/web/db.py", line 538, in __getitem__
    return next(self)
  File "/usr/local/lib/python3.10/dist-packages/web/db.py", line 510, in __next__
    raise StopIteration()
StopIteration

During handling of the above exception, another exception occurred:

Traceback (most recent call last):
  File "app.py", line 40, in wrapper
    return func(*args,**kwargs)
  File "app.py", line 99, in POST
    result = Account.verifyAccount(userId,password)
  File "/home/weihong/backendFrame/webpy/./Account.py", line 124, in verifyAccount
    print(result[0]['password'])
  File "/usr/local/lib/python3.10/dist-packages/web/db.py", line 540, in __getitem__
    raise IndexError(str(i))
IndexError: 0
2024-08-24 18:35:05|ERROR|app.py:43|already passed 0
Traceback (most recent call last):
  File "app.py", line 40, in wrapper
    return func(*args,**kwargs)
  File "app.py", line 99, in POST
    result = Account.verifyAccount(userId,password)
  File "/home/weihong/backendFrame/webpy/./Account.py", line 129, in verifyAccount
    if result[0]['password'] != password:
  File "/usr/local/lib/python3.10/dist-packages/web/db.py", line 531, in __getitem__
    raise IndexError("already passed " + str(i))
IndexError: already passed 0
2024-08-24 18:37:16|ERROR|app.py:43|(1292, "Truncated incorrect DOUBLE value: '19903236282aaa'")
Traceback (most recent call last):
  File "app.py", line 40, in wrapper
    return func(*args,**kwargs)
  File "app.py", line 107, in POST
    result = Account.handleLogin(userId, session)
  File "/home/weihong/backendFrame/webpy/./Account.py", line 146, in handleLogin
    DBManage.updateLastLoginTime(userId,now)
  File "/home/weihong/backendFrame/webpy/./DBManage.py", line 25, in updateLastLoginTime
    Config.gdb.update(
  File "/usr/local/lib/python3.10/dist-packages/web/db.py", line 1145, in update
    self._db_execute(db_cursor, query)
  File "/usr/local/lib/python3.10/dist-packages/web/db.py", line 764, in _db_execute
    out = cur.execute(query, params)
  File "/usr/local/lib/python3.10/dist-packages/pymysql/cursors.py", line 153, in execute
    result = self._query(query)
  File "/usr/local/lib/python3.10/dist-packages/pymysql/cursors.py", line 322, in _query
    conn.query(q)
  File "/usr/local/lib/python3.10/dist-packages/pymysql/connections.py", line 563, in query
    self._affected_rows = self._read_query_result(unbuffered=unbuffered)
  File "/usr/local/lib/python3.10/dist-packages/pymysql/connections.py", line 825, in _read_query_result
    result.read()
  File "/usr/local/lib/python3.10/dist-packages/pymysql/connections.py", line 1199, in read
    first_packet = self.connection._read_packet()
  File "/usr/local/lib/python3.10/dist-packages/pymysql/connections.py", line 775, in _read_packet
    packet.raise_for_error()
  File "/usr/local/lib/python3.10/dist-packages/pymysql/protocol.py", line 219, in raise_for_error
    err.raise_mysql_exception(self._data)
  File "/usr/local/lib/python3.10/dist-packages/pymysql/err.py", line 150, in raise_mysql_exception
    raise errorclass(errno, errval)
pymysql.err.OperationalError: (1292, "Truncated incorrect DOUBLE value: '19903236282aaa'")
2024-08-24 18:37:26|ERROR|app.py:43|already passed 0
Traceback (most recent call last):
  File "app.py", line 40, in wrapper
    return func(*args,**kwargs)
  File "app.py", line 99, in POST
    result = Account.verifyAccount(userId,password)
  File "/home/weihong/backendFrame/webpy/./Account.py", line 129, in verifyAccount
    if result[0]['password'] != password:
  File "/usr/local/lib/python3.10/dist-packages/web/db.py", line 531, in __getitem__
    raise IndexError("already passed " + str(i))
IndexError: already passed 0
2024-08-24 18:37:31|ERROR|app.py:43|already passed 0
Traceback (most recent call last):
  File "app.py", line 40, in wrapper
    return func(*args,**kwargs)
  File "app.py", line 99, in POST
    result = Account.verifyAccount(userId,password)
  File "/home/weihong/backendFrame/webpy/./Account.py", line 129, in verifyAccount
    if result[0]['password'] != password:
  File "/usr/local/lib/python3.10/dist-packages/web/db.py", line 531, in __getitem__
    raise IndexError("already passed " + str(i))
IndexError: already passed 0
2024-08-24 18:37:35|ERROR|app.py:43|already passed 0
Traceback (most recent call last):
  File "app.py", line 40, in wrapper
    return func(*args,**kwargs)
  File "app.py", line 99, in POST
    result = Account.verifyAccount(userId,password)
  File "/home/weihong/backendFrame/webpy/./Account.py", line 129, in verifyAccount
    if result[0]['password'] != password:
  File "/usr/local/lib/python3.10/dist-packages/web/db.py", line 531, in __getitem__
    raise IndexError("already passed " + str(i))
IndexError: already passed 0
2024-08-24 18:48:55|ERROR|app.py:43|invalid literal for int() with base 10: '19903236282asdasd'
Traceback (most recent call last):
  File "app.py", line 40, in wrapper
    return func(*args,**kwargs)
  File "app.py", line 96, in POST
    result = Account.verifyAccount(userId,password)
  File "/home/weihong/backendFrame/webpy/./Account.py", line 119, in verifyAccount
    userId = int(userId)
ValueError: invalid literal for int() with base 10: '19903236282asdasd'
2024-08-24 18:49:34|ERROR|app.py:43|invalid literal for int() with base 10: '1990323628a'
Traceback (most recent call last):
  File "app.py", line 40, in wrapper
    return func(*args,**kwargs)
  File "app.py", line 96, in POST
    result = Account.verifyAccount(userId,password)
  File "/home/weihong/backendFrame/webpy/./Account.py", line 119, in verifyAccount
    userId = int(userId)
ValueError: invalid literal for int() with base 10: '1990323628a'
2024-08-24 18:49:39|ERROR|app.py:43|invalid literal for int() with base 10: '1990323628a'
Traceback (most recent call last):
  File "app.py", line 40, in wrapper
    return func(*args,**kwargs)
  File "app.py", line 96, in POST
    result = Account.verifyAccount(userId,password)
  File "/home/weihong/backendFrame/webpy/./Account.py", line 119, in verifyAccount
    userId = int(userId)
ValueError: invalid literal for int() with base 10: '1990323628a'
2024-08-24 18:49:40|ERROR|app.py:43|invalid literal for int() with base 10: '1990323628a'
Traceback (most recent call last):
  File "app.py", line 40, in wrapper
    return func(*args,**kwargs)
  File "app.py", line 96, in POST
    result = Account.verifyAccount(userId,password)
  File "/home/weihong/backendFrame/webpy/./Account.py", line 119, in verifyAccount
    userId = int(userId)
ValueError: invalid literal for int() with base 10: '1990323628a'
2024-08-24 18:56:52|ERROR|app.py:43|0
Traceback (most recent call last):
  File "/usr/local/lib/python3.10/dist-packages/web/db.py", line 538, in __getitem__
    return next(self)
  File "/usr/local/lib/python3.10/dist-packages/web/db.py", line 510, in __next__
    raise StopIteration()
StopIteration

During handling of the above exception, another exception occurred:

Traceback (most recent call last):
  File "app.py", line 40, in wrapper
    return func(*args,**kwargs)
  File "app.py", line 96, in POST
    result = Account.verifyAccount(userId,password)
  File "/home/weihong/backendFrame/webpy/./Account.py", line 126, in verifyAccount
    if result[0]['password'] != password:
  File "/usr/local/lib/python3.10/dist-packages/web/db.py", line 540, in __getitem__
    raise IndexError(str(i))
IndexError: 0
2024-08-24 18:57:19|ERROR|app.py:43|0
Traceback (most recent call last):
  File "/usr/local/lib/python3.10/dist-packages/web/db.py", line 538, in __getitem__
    return next(self)
  File "/usr/local/lib/python3.10/dist-packages/web/db.py", line 510, in __next__
    raise StopIteration()
StopIteration

During handling of the above exception, another exception occurred:

Traceback (most recent call last):
  File "app.py", line 40, in wrapper
    return func(*args,**kwargs)
  File "app.py", line 96, in POST
    result = Account.verifyAccount(userId,password)
  File "/home/weihong/backendFrame/webpy/./Account.py", line 126, in verifyAccount
    if result[0]['password'] != password:
  File "/usr/local/lib/python3.10/dist-packages/web/db.py", line 540, in __getitem__
    raise IndexError(str(i))
IndexError: 0
2024-08-24 18:57:45|ERROR|app.py:43|(1292, "Truncated incorrect DOUBLE value: '19903236282a'")
Traceback (most recent call last):
  File "app.py", line 40, in wrapper
    return func(*args,**kwargs)
  File "app.py", line 102, in POST
    result = Account.handleLogin(userId, session)
  File "/home/weihong/backendFrame/webpy/./Account.py", line 143, in handleLogin
    DBManage.updateLastLoginTime(userId,now)
  File "/home/weihong/backendFrame/webpy/./DBManage.py", line 25, in updateLastLoginTime
    Config.gdb.update(
  File "/usr/local/lib/python3.10/dist-packages/web/db.py", line 1145, in update
    self._db_execute(db_cursor, query)
  File "/usr/local/lib/python3.10/dist-packages/web/db.py", line 764, in _db_execute
    out = cur.execute(query, params)
  File "/usr/local/lib/python3.10/dist-packages/pymysql/cursors.py", line 153, in execute
    result = self._query(query)
  File "/usr/local/lib/python3.10/dist-packages/pymysql/cursors.py", line 322, in _query
    conn.query(q)
  File "/usr/local/lib/python3.10/dist-packages/pymysql/connections.py", line 563, in query
    self._affected_rows = self._read_query_result(unbuffered=unbuffered)
  File "/usr/local/lib/python3.10/dist-packages/pymysql/connections.py", line 825, in _read_query_result
    result.read()
  File "/usr/local/lib/python3.10/dist-packages/pymysql/connections.py", line 1199, in read
    first_packet = self.connection._read_packet()
  File "/usr/local/lib/python3.10/dist-packages/pymysql/connections.py", line 775, in _read_packet
    packet.raise_for_error()
  File "/usr/local/lib/python3.10/dist-packages/pymysql/protocol.py", line 219, in raise_for_error
    err.raise_mysql_exception(self._data)
  File "/usr/local/lib/python3.10/dist-packages/pymysql/err.py", line 150, in raise_mysql_exception
    raise errorclass(errno, errval)
pymysql.err.OperationalError: (1292, "Truncated incorrect DOUBLE value: '19903236282a'")
2024-08-24 18:59:27|ERROR|app.py:43|(1292, "Truncated incorrect DOUBLE value: '19903236282a'")
Traceback (most recent call last):
  File "app.py", line 40, in wrapper
    return func(*args,**kwargs)
  File "app.py", line 102, in POST
    result = Account.handleLogin(userId, session)
  File "/home/weihong/backendFrame/webpy/./Account.py", line 143, in handleLogin
    DBManage.updateLastLoginTime(userId,now)
  File "/home/weihong/backendFrame/webpy/./DBManage.py", line 25, in updateLastLoginTime
    Config.gdb.update(
  File "/usr/local/lib/python3.10/dist-packages/web/db.py", line 1145, in update
    self._db_execute(db_cursor, query)
  File "/usr/local/lib/python3.10/dist-packages/web/db.py", line 764, in _db_execute
    out = cur.execute(query, params)
  File "/usr/local/lib/python3.10/dist-packages/pymysql/cursors.py", line 153, in execute
    result = self._query(query)
  File "/usr/local/lib/python3.10/dist-packages/pymysql/cursors.py", line 322, in _query
    conn.query(q)
  File "/usr/local/lib/python3.10/dist-packages/pymysql/connections.py", line 563, in query
    self._affected_rows = self._read_query_result(unbuffered=unbuffered)
  File "/usr/local/lib/python3.10/dist-packages/pymysql/connections.py", line 825, in _read_query_result
    result.read()
  File "/usr/local/lib/python3.10/dist-packages/pymysql/connections.py", line 1199, in read
    first_packet = self.connection._read_packet()
  File "/usr/local/lib/python3.10/dist-packages/pymysql/connections.py", line 775, in _read_packet
    packet.raise_for_error()
  File "/usr/local/lib/python3.10/dist-packages/pymysql/protocol.py", line 219, in raise_for_error
    err.raise_mysql_exception(self._data)
  File "/usr/local/lib/python3.10/dist-packages/pymysql/err.py", line 150, in raise_mysql_exception
    raise errorclass(errno, errval)
pymysql.err.OperationalError: (1292, "Truncated incorrect DOUBLE value: '19903236282a'")
2024-08-24 18:59:57|ERROR|app.py:43|(1292, "Truncated incorrect DOUBLE value: '19903236282a'")
Traceback (most recent call last):
  File "app.py", line 40, in wrapper
    return func(*args,**kwargs)
  File "app.py", line 102, in POST
    result = Account.handleLogin(userId, session)
  File "/home/weihong/backendFrame/webpy/./Account.py", line 143, in handleLogin
    DBManage.updateLastLoginTime(userId,now)
  File "/home/weihong/backendFrame/webpy/./DBManage.py", line 25, in updateLastLoginTime
    Config.gdb.update(
  File "/usr/local/lib/python3.10/dist-packages/web/db.py", line 1145, in update
    self._db_execute(db_cursor, query)
  File "/usr/local/lib/python3.10/dist-packages/web/db.py", line 764, in _db_execute
    out = cur.execute(query, params)
  File "/usr/local/lib/python3.10/dist-packages/pymysql/cursors.py", line 153, in execute
    result = self._query(query)
  File "/usr/local/lib/python3.10/dist-packages/pymysql/cursors.py", line 322, in _query
    conn.query(q)
  File "/usr/local/lib/python3.10/dist-packages/pymysql/connections.py", line 563, in query
    self._affected_rows = self._read_query_result(unbuffered=unbuffered)
  File "/usr/local/lib/python3.10/dist-packages/pymysql/connections.py", line 825, in _read_query_result
    result.read()
  File "/usr/local/lib/python3.10/dist-packages/pymysql/connections.py", line 1199, in read
    first_packet = self.connection._read_packet()
  File "/usr/local/lib/python3.10/dist-packages/pymysql/connections.py", line 775, in _read_packet
    packet.raise_for_error()
  File "/usr/local/lib/python3.10/dist-packages/pymysql/protocol.py", line 219, in raise_for_error
    err.raise_mysql_exception(self._data)
  File "/usr/local/lib/python3.10/dist-packages/pymysql/err.py", line 150, in raise_mysql_exception
    raise errorclass(errno, errval)
pymysql.err.OperationalError: (1292, "Truncated incorrect DOUBLE value: '19903236282a'")
2024-08-24 19:02:20|ERROR|app.py:43|'dict' object has no attribute 'has_key'
Traceback (most recent call last):
  File "app.py", line 40, in wrapper
    return func(*args,**kwargs)
  File "app.py", line 49, in wrapper
    if session.__dict__.has_key('userid'):
AttributeError: 'dict' object has no attribute 'has_key'
2024-08-24 19:10:40|ERROR|app.py:43|(1292, "Truncated incorrect DOUBLE value: '19903236282a'")
Traceback (most recent call last):
  File "app.py", line 40, in wrapper
    return func(*args,**kwargs)
  File "app.py", line 102, in POST
    result = Account.handleLogin(userId, session)
  File "/home/weihong/backendFrame/webpy/./Account.py", line 143, in handleLogin
    DBManage.updateLastLoginTime(userId,now)
  File "/home/weihong/backendFrame/webpy/./DBManage.py", line 25, in updateLastLoginTime
    Config.gdb.update(
  File "/usr/local/lib/python3.10/dist-packages/web/db.py", line 1145, in update
    self._db_execute(db_cursor, query)
  File "/usr/local/lib/python3.10/dist-packages/web/db.py", line 764, in _db_execute
    out = cur.execute(query, params)
  File "/usr/local/lib/python3.10/dist-packages/pymysql/cursors.py", line 153, in execute
    result = self._query(query)
  File "/usr/local/lib/python3.10/dist-packages/pymysql/cursors.py", line 322, in _query
    conn.query(q)
  File "/usr/local/lib/python3.10/dist-packages/pymysql/connections.py", line 563, in query
    self._affected_rows = self._read_query_result(unbuffered=unbuffered)
  File "/usr/local/lib/python3.10/dist-packages/pymysql/connections.py", line 825, in _read_query_result
    result.read()
  File "/usr/local/lib/python3.10/dist-packages/pymysql/connections.py", line 1199, in read
    first_packet = self.connection._read_packet()
  File "/usr/local/lib/python3.10/dist-packages/pymysql/connections.py", line 775, in _read_packet
    packet.raise_for_error()
  File "/usr/local/lib/python3.10/dist-packages/pymysql/protocol.py", line 219, in raise_for_error
    err.raise_mysql_exception(self._data)
  File "/usr/local/lib/python3.10/dist-packages/pymysql/err.py", line 150, in raise_mysql_exception
    raise errorclass(errno, errval)
pymysql.err.OperationalError: (1292, "Truncated incorrect DOUBLE value: '19903236282a'")
2024-08-24 19:11:01|ERROR|app.py:43|(1292, "Truncated incorrect DOUBLE value: '19903236282a'")
Traceback (most recent call last):
  File "app.py", line 40, in wrapper
    return func(*args,**kwargs)
  File "app.py", line 102, in POST
    result = Account.handleLogin(userId, session)
  File "/home/weihong/backendFrame/webpy/./Account.py", line 143, in handleLogin
    DBManage.updateLastLoginTime(userId,now)
  File "/home/weihong/backendFrame/webpy/./DBManage.py", line 25, in updateLastLoginTime
    Config.gdb.update(
  File "/usr/local/lib/python3.10/dist-packages/web/db.py", line 1145, in update
    self._db_execute(db_cursor, query)
  File "/usr/local/lib/python3.10/dist-packages/web/db.py", line 764, in _db_execute
    out = cur.execute(query, params)
  File "/usr/local/lib/python3.10/dist-packages/pymysql/cursors.py", line 153, in execute
    result = self._query(query)
  File "/usr/local/lib/python3.10/dist-packages/pymysql/cursors.py", line 322, in _query
    conn.query(q)
  File "/usr/local/lib/python3.10/dist-packages/pymysql/connections.py", line 563, in query
    self._affected_rows = self._read_query_result(unbuffered=unbuffered)
  File "/usr/local/lib/python3.10/dist-packages/pymysql/connections.py", line 825, in _read_query_result
    result.read()
  File "/usr/local/lib/python3.10/dist-packages/pymysql/connections.py", line 1199, in read
    first_packet = self.connection._read_packet()
  File "/usr/local/lib/python3.10/dist-packages/pymysql/connections.py", line 775, in _read_packet
    packet.raise_for_error()
  File "/usr/local/lib/python3.10/dist-packages/pymysql/protocol.py", line 219, in raise_for_error
    err.raise_mysql_exception(self._data)
  File "/usr/local/lib/python3.10/dist-packages/pymysql/err.py", line 150, in raise_mysql_exception
    raise errorclass(errno, errval)
pymysql.err.OperationalError: (1292, "Truncated incorrect DOUBLE value: '19903236282a'")
2024-08-24 19:13:07|ERROR|app.py:43|(1292, "Truncated incorrect DOUBLE value: '19903236282a'")
Traceback (most recent call last):
  File "app.py", line 40, in wrapper
    return func(*args,**kwargs)
  File "app.py", line 102, in POST
    result = Account.handleLogin(userId, session)
  File "/home/weihong/backendFrame/webpy/./Account.py", line 143, in handleLogin
    DBManage.updateLastLoginTime(userId,now)
  File "/home/weihong/backendFrame/webpy/./DBManage.py", line 25, in updateLastLoginTime
    Config.gdb.update(
  File "/usr/local/lib/python3.10/dist-packages/web/db.py", line 1145, in update
    self._db_execute(db_cursor, query)
  File "/usr/local/lib/python3.10/dist-packages/web/db.py", line 764, in _db_execute
    out = cur.execute(query, params)
  File "/usr/local/lib/python3.10/dist-packages/pymysql/cursors.py", line 153, in execute
    result = self._query(query)
  File "/usr/local/lib/python3.10/dist-packages/pymysql/cursors.py", line 322, in _query
    conn.query(q)
  File "/usr/local/lib/python3.10/dist-packages/pymysql/connections.py", line 563, in query
    self._affected_rows = self._read_query_result(unbuffered=unbuffered)
  File "/usr/local/lib/python3.10/dist-packages/pymysql/connections.py", line 825, in _read_query_result
    result.read()
  File "/usr/local/lib/python3.10/dist-packages/pymysql/connections.py", line 1199, in read
    first_packet = self.connection._read_packet()
  File "/usr/local/lib/python3.10/dist-packages/pymysql/connections.py", line 775, in _read_packet
    packet.raise_for_error()
  File "/usr/local/lib/python3.10/dist-packages/pymysql/protocol.py", line 219, in raise_for_error
    err.raise_mysql_exception(self._data)
  File "/usr/local/lib/python3.10/dist-packages/pymysql/err.py", line 150, in raise_mysql_exception
    raise errorclass(errno, errval)
pymysql.err.OperationalError: (1292, "Truncated incorrect DOUBLE value: '19903236282a'")
2024-08-24 19:13:50|ERROR|app.py:43|(1292, "Truncated incorrect DOUBLE value: '19903236281a'")
Traceback (most recent call last):
  File "app.py", line 40, in wrapper
    return func(*args,**kwargs)
  File "app.py", line 102, in POST
    result = Account.handleLogin(userId, session)
  File "/home/weihong/backendFrame/webpy/./Account.py", line 143, in handleLogin
    DBManage.updateLastLoginTime(userId,now)
  File "/home/weihong/backendFrame/webpy/./DBManage.py", line 25, in updateLastLoginTime
    Config.gdb.update(
  File "/usr/local/lib/python3.10/dist-packages/web/db.py", line 1145, in update
    self._db_execute(db_cursor, query)
  File "/usr/local/lib/python3.10/dist-packages/web/db.py", line 764, in _db_execute
    out = cur.execute(query, params)
  File "/usr/local/lib/python3.10/dist-packages/pymysql/cursors.py", line 153, in execute
    result = self._query(query)
  File "/usr/local/lib/python3.10/dist-packages/pymysql/cursors.py", line 322, in _query
    conn.query(q)
  File "/usr/local/lib/python3.10/dist-packages/pymysql/connections.py", line 563, in query
    self._affected_rows = self._read_query_result(unbuffered=unbuffered)
  File "/usr/local/lib/python3.10/dist-packages/pymysql/connections.py", line 825, in _read_query_result
    result.read()
  File "/usr/local/lib/python3.10/dist-packages/pymysql/connections.py", line 1199, in read
    first_packet = self.connection._read_packet()
  File "/usr/local/lib/python3.10/dist-packages/pymysql/connections.py", line 775, in _read_packet
    packet.raise_for_error()
  File "/usr/local/lib/python3.10/dist-packages/pymysql/protocol.py", line 219, in raise_for_error
    err.raise_mysql_exception(self._data)
  File "/usr/local/lib/python3.10/dist-packages/pymysql/err.py", line 150, in raise_mysql_exception
    raise errorclass(errno, errval)
pymysql.err.OperationalError: (1292, "Truncated incorrect DOUBLE value: '19903236281a'")
2024-08-24 19:13:53|ERROR|app.py:43|(1292, "Truncated incorrect DOUBLE value: '19903236281a'")
Traceback (most recent call last):
  File "app.py", line 40, in wrapper
    return func(*args,**kwargs)
  File "app.py", line 102, in POST
    result = Account.handleLogin(userId, session)
  File "/home/weihong/backendFrame/webpy/./Account.py", line 143, in handleLogin
    DBManage.updateLastLoginTime(userId,now)
  File "/home/weihong/backendFrame/webpy/./DBManage.py", line 25, in updateLastLoginTime
    Config.gdb.update(
  File "/usr/local/lib/python3.10/dist-packages/web/db.py", line 1145, in update
    self._db_execute(db_cursor, query)
  File "/usr/local/lib/python3.10/dist-packages/web/db.py", line 764, in _db_execute
    out = cur.execute(query, params)
  File "/usr/local/lib/python3.10/dist-packages/pymysql/cursors.py", line 153, in execute
    result = self._query(query)
  File "/usr/local/lib/python3.10/dist-packages/pymysql/cursors.py", line 322, in _query
    conn.query(q)
  File "/usr/local/lib/python3.10/dist-packages/pymysql/connections.py", line 563, in query
    self._affected_rows = self._read_query_result(unbuffered=unbuffered)
  File "/usr/local/lib/python3.10/dist-packages/pymysql/connections.py", line 825, in _read_query_result
    result.read()
  File "/usr/local/lib/python3.10/dist-packages/pymysql/connections.py", line 1199, in read
    first_packet = self.connection._read_packet()
  File "/usr/local/lib/python3.10/dist-packages/pymysql/connections.py", line 775, in _read_packet
    packet.raise_for_error()
  File "/usr/local/lib/python3.10/dist-packages/pymysql/protocol.py", line 219, in raise_for_error
    err.raise_mysql_exception(self._data)
  File "/usr/local/lib/python3.10/dist-packages/pymysql/err.py", line 150, in raise_mysql_exception
    raise errorclass(errno, errval)
pymysql.err.OperationalError: (1292, "Truncated incorrect DOUBLE value: '19903236281a'")
2024-08-24 19:13:57|ERROR|app.py:43|0
Traceback (most recent call last):
  File "/usr/local/lib/python3.10/dist-packages/web/db.py", line 538, in __getitem__
    return next(self)
  File "/usr/local/lib/python3.10/dist-packages/web/db.py", line 510, in __next__
    raise StopIteration()
StopIteration

During handling of the above exception, another exception occurred:

Traceback (most recent call last):
  File "app.py", line 40, in wrapper
    return func(*args,**kwargs)
  File "app.py", line 96, in POST
    result = Account.verifyAccount(userId,password)
  File "/home/weihong/backendFrame/webpy/./Account.py", line 131, in verifyAccount
    if result[0]['status'] == Config.USER_STATUS_FRERZE:
  File "/usr/local/lib/python3.10/dist-packages/web/db.py", line 540, in __getitem__
    raise IndexError(str(i))
IndexError: 0
2024-08-24 19:14:01|ERROR|app.py:43|0
Traceback (most recent call last):
  File "/usr/local/lib/python3.10/dist-packages/web/db.py", line 538, in __getitem__
    return next(self)
  File "/usr/local/lib/python3.10/dist-packages/web/db.py", line 510, in __next__
    raise StopIteration()
StopIteration

During handling of the above exception, another exception occurred:

Traceback (most recent call last):
  File "app.py", line 40, in wrapper
    return func(*args,**kwargs)
  File "app.py", line 96, in POST
    result = Account.verifyAccount(userId,password)
  File "/home/weihong/backendFrame/webpy/./Account.py", line 131, in verifyAccount
    if result[0]['status'] == Config.USER_STATUS_FRERZE:
  File "/usr/local/lib/python3.10/dist-packages/web/db.py", line 540, in __getitem__
    raise IndexError(str(i))
IndexError: 0
2024-08-24 19:15:24|ERROR|app.py:43|(1292, "Truncated incorrect DOUBLE value: '19903236281a'")
Traceback (most recent call last):
  File "app.py", line 40, in wrapper
    return func(*args,**kwargs)
  File "app.py", line 102, in POST
    result = Account.handleLogin(userId, session)
  File "/home/weihong/backendFrame/webpy/./Account.py", line 143, in handleLogin
    DBManage.updateLastLoginTime(userId,now)
  File "/home/weihong/backendFrame/webpy/./DBManage.py", line 25, in updateLastLoginTime
    Config.gdb.update(
  File "/usr/local/lib/python3.10/dist-packages/web/db.py", line 1145, in update
    self._db_execute(db_cursor, query)
  File "/usr/local/lib/python3.10/dist-packages/web/db.py", line 764, in _db_execute
    out = cur.execute(query, params)
  File "/usr/local/lib/python3.10/dist-packages/pymysql/cursors.py", line 153, in execute
    result = self._query(query)
  File "/usr/local/lib/python3.10/dist-packages/pymysql/cursors.py", line 322, in _query
    conn.query(q)
  File "/usr/local/lib/python3.10/dist-packages/pymysql/connections.py", line 563, in query
    self._affected_rows = self._read_query_result(unbuffered=unbuffered)
  File "/usr/local/lib/python3.10/dist-packages/pymysql/connections.py", line 825, in _read_query_result
    result.read()
  File "/usr/local/lib/python3.10/dist-packages/pymysql/connections.py", line 1199, in read
    first_packet = self.connection._read_packet()
  File "/usr/local/lib/python3.10/dist-packages/pymysql/connections.py", line 775, in _read_packet
    packet.raise_for_error()
  File "/usr/local/lib/python3.10/dist-packages/pymysql/protocol.py", line 219, in raise_for_error
    err.raise_mysql_exception(self._data)
  File "/usr/local/lib/python3.10/dist-packages/pymysql/err.py", line 150, in raise_mysql_exception
    raise errorclass(errno, errval)
pymysql.err.OperationalError: (1292, "Truncated incorrect DOUBLE value: '19903236281a'")
2024-08-24 19:15:30|ERROR|app.py:43|0
Traceback (most recent call last):
  File "/usr/local/lib/python3.10/dist-packages/web/db.py", line 538, in __getitem__
    return next(self)
  File "/usr/local/lib/python3.10/dist-packages/web/db.py", line 510, in __next__
    raise StopIteration()
StopIteration

During handling of the above exception, another exception occurred:

Traceback (most recent call last):
  File "app.py", line 40, in wrapper
    return func(*args,**kwargs)
  File "app.py", line 96, in POST
    result = Account.verifyAccount(userId,password)
  File "/home/weihong/backendFrame/webpy/./Account.py", line 131, in verifyAccount
    if result[0]['status'] == Config.USER_STATUS_FRERZE:
  File "/usr/local/lib/python3.10/dist-packages/web/db.py", line 540, in __getitem__
    raise IndexError(str(i))
IndexError: 0
2024-08-24 19:16:21|ERROR|app.py:43|(1292, "Truncated incorrect DOUBLE value: '19903236281a'")
Traceback (most recent call last):
  File "app.py", line 40, in wrapper
    return func(*args,**kwargs)
  File "app.py", line 102, in POST
    result = Account.handleLogin(userId, session)
  File "/home/weihong/backendFrame/webpy/./Account.py", line 143, in handleLogin
    DBManage.updateLastLoginTime(userId,now)
  File "/home/weihong/backendFrame/webpy/./DBManage.py", line 25, in updateLastLoginTime
    Config.gdb.update(
  File "/usr/local/lib/python3.10/dist-packages/web/db.py", line 1145, in update
    self._db_execute(db_cursor, query)
  File "/usr/local/lib/python3.10/dist-packages/web/db.py", line 764, in _db_execute
    out = cur.execute(query, params)
  File "/usr/local/lib/python3.10/dist-packages/pymysql/cursors.py", line 153, in execute
    result = self._query(query)
  File "/usr/local/lib/python3.10/dist-packages/pymysql/cursors.py", line 322, in _query
    conn.query(q)
  File "/usr/local/lib/python3.10/dist-packages/pymysql/connections.py", line 563, in query
    self._affected_rows = self._read_query_result(unbuffered=unbuffered)
  File "/usr/local/lib/python3.10/dist-packages/pymysql/connections.py", line 825, in _read_query_result
    result.read()
  File "/usr/local/lib/python3.10/dist-packages/pymysql/connections.py", line 1199, in read
    first_packet = self.connection._read_packet()
  File "/usr/local/lib/python3.10/dist-packages/pymysql/connections.py", line 775, in _read_packet
    packet.raise_for_error()
  File "/usr/local/lib/python3.10/dist-packages/pymysql/protocol.py", line 219, in raise_for_error
    err.raise_mysql_exception(self._data)
  File "/usr/local/lib/python3.10/dist-packages/pymysql/err.py", line 150, in raise_mysql_exception
    raise errorclass(errno, errval)
pymysql.err.OperationalError: (1292, "Truncated incorrect DOUBLE value: '19903236281a'")
2024-08-24 19:16:46|ERROR|app.py:43|(1292, "Truncated incorrect DOUBLE value: '19903236281a'")
Traceback (most recent call last):
  File "app.py", line 40, in wrapper
    return func(*args,**kwargs)
  File "app.py", line 102, in POST
    result = Account.handleLogin(userId, session)
  File "/home/weihong/backendFrame/webpy/./Account.py", line 143, in handleLogin
    DBManage.updateLastLoginTime(userId,now)
  File "/home/weihong/backendFrame/webpy/./DBManage.py", line 25, in updateLastLoginTime
    Config.gdb.update(
  File "/usr/local/lib/python3.10/dist-packages/web/db.py", line 1145, in update
    self._db_execute(db_cursor, query)
  File "/usr/local/lib/python3.10/dist-packages/web/db.py", line 764, in _db_execute
    out = cur.execute(query, params)
  File "/usr/local/lib/python3.10/dist-packages/pymysql/cursors.py", line 153, in execute
    result = self._query(query)
  File "/usr/local/lib/python3.10/dist-packages/pymysql/cursors.py", line 322, in _query
    conn.query(q)
  File "/usr/local/lib/python3.10/dist-packages/pymysql/connections.py", line 563, in query
    self._affected_rows = self._read_query_result(unbuffered=unbuffered)
  File "/usr/local/lib/python3.10/dist-packages/pymysql/connections.py", line 825, in _read_query_result
    result.read()
  File "/usr/local/lib/python3.10/dist-packages/pymysql/connections.py", line 1199, in read
    first_packet = self.connection._read_packet()
  File "/usr/local/lib/python3.10/dist-packages/pymysql/connections.py", line 775, in _read_packet
    packet.raise_for_error()
  File "/usr/local/lib/python3.10/dist-packages/pymysql/protocol.py", line 219, in raise_for_error
    err.raise_mysql_exception(self._data)
  File "/usr/local/lib/python3.10/dist-packages/pymysql/err.py", line 150, in raise_mysql_exception
    raise errorclass(errno, errval)
pymysql.err.OperationalError: (1292, "Truncated incorrect DOUBLE value: '19903236281a'")
2024-08-24 19:17:08|ERROR|app.py:43|(1292, "Truncated incorrect DOUBLE value: '19903236281a'")
Traceback (most recent call last):
  File "app.py", line 40, in wrapper
    return func(*args,**kwargs)
  File "app.py", line 102, in POST
    result = Account.handleLogin(userId, session)
  File "/home/weihong/backendFrame/webpy/./Account.py", line 143, in handleLogin
    DBManage.updateLastLoginTime(userId,now)
  File "/home/weihong/backendFrame/webpy/./DBManage.py", line 25, in updateLastLoginTime
    Config.gdb.update(
  File "/usr/local/lib/python3.10/dist-packages/web/db.py", line 1145, in update
    self._db_execute(db_cursor, query)
  File "/usr/local/lib/python3.10/dist-packages/web/db.py", line 764, in _db_execute
    out = cur.execute(query, params)
  File "/usr/local/lib/python3.10/dist-packages/pymysql/cursors.py", line 153, in execute
    result = self._query(query)
  File "/usr/local/lib/python3.10/dist-packages/pymysql/cursors.py", line 322, in _query
    conn.query(q)
  File "/usr/local/lib/python3.10/dist-packages/pymysql/connections.py", line 563, in query
    self._affected_rows = self._read_query_result(unbuffered=unbuffered)
  File "/usr/local/lib/python3.10/dist-packages/pymysql/connections.py", line 825, in _read_query_result
    result.read()
  File "/usr/local/lib/python3.10/dist-packages/pymysql/connections.py", line 1199, in read
    first_packet = self.connection._read_packet()
  File "/usr/local/lib/python3.10/dist-packages/pymysql/connections.py", line 775, in _read_packet
    packet.raise_for_error()
  File "/usr/local/lib/python3.10/dist-packages/pymysql/protocol.py", line 219, in raise_for_error
    err.raise_mysql_exception(self._data)
  File "/usr/local/lib/python3.10/dist-packages/pymysql/err.py", line 150, in raise_mysql_exception
    raise errorclass(errno, errval)
pymysql.err.OperationalError: (1292, "Truncated incorrect DOUBLE value: '19903236281a'")
2024-08-24 19:17:28|ERROR|app.py:43|(1292, "Truncated incorrect DOUBLE value: '19903236281aaa'")
Traceback (most recent call last):
  File "app.py", line 40, in wrapper
    return func(*args,**kwargs)
  File "app.py", line 102, in POST
    result = Account.handleLogin(userId, session)
  File "/home/weihong/backendFrame/webpy/./Account.py", line 143, in handleLogin
    DBManage.updateLastLoginTime(userId,now)
  File "/home/weihong/backendFrame/webpy/./DBManage.py", line 25, in updateLastLoginTime
    Config.gdb.update(
  File "/usr/local/lib/python3.10/dist-packages/web/db.py", line 1145, in update
    self._db_execute(db_cursor, query)
  File "/usr/local/lib/python3.10/dist-packages/web/db.py", line 764, in _db_execute
    out = cur.execute(query, params)
  File "/usr/local/lib/python3.10/dist-packages/pymysql/cursors.py", line 153, in execute
    result = self._query(query)
  File "/usr/local/lib/python3.10/dist-packages/pymysql/cursors.py", line 322, in _query
    conn.query(q)
  File "/usr/local/lib/python3.10/dist-packages/pymysql/connections.py", line 563, in query
    self._affected_rows = self._read_query_result(unbuffered=unbuffered)
  File "/usr/local/lib/python3.10/dist-packages/pymysql/connections.py", line 825, in _read_query_result
    result.read()
  File "/usr/local/lib/python3.10/dist-packages/pymysql/connections.py", line 1199, in read
    first_packet = self.connection._read_packet()
  File "/usr/local/lib/python3.10/dist-packages/pymysql/connections.py", line 775, in _read_packet
    packet.raise_for_error()
  File "/usr/local/lib/python3.10/dist-packages/pymysql/protocol.py", line 219, in raise_for_error
    err.raise_mysql_exception(self._data)
  File "/usr/local/lib/python3.10/dist-packages/pymysql/err.py", line 150, in raise_mysql_exception
    raise errorclass(errno, errval)
pymysql.err.OperationalError: (1292, "Truncated incorrect DOUBLE value: '19903236281aaa'")
2024-08-24 19:17:41|ERROR|app.py:43|(1292, "Truncated incorrect DOUBLE value: '19903236281aaa'")
Traceback (most recent call last):
  File "app.py", line 40, in wrapper
    return func(*args,**kwargs)
  File "app.py", line 102, in POST
    result = Account.handleLogin(userId, session)
  File "/home/weihong/backendFrame/webpy/./Account.py", line 143, in handleLogin
    DBManage.updateLastLoginTime(userId,now)
  File "/home/weihong/backendFrame/webpy/./DBManage.py", line 25, in updateLastLoginTime
    Config.gdb.update(
  File "/usr/local/lib/python3.10/dist-packages/web/db.py", line 1145, in update
    self._db_execute(db_cursor, query)
  File "/usr/local/lib/python3.10/dist-packages/web/db.py", line 764, in _db_execute
    out = cur.execute(query, params)
  File "/usr/local/lib/python3.10/dist-packages/pymysql/cursors.py", line 153, in execute
    result = self._query(query)
  File "/usr/local/lib/python3.10/dist-packages/pymysql/cursors.py", line 322, in _query
    conn.query(q)
  File "/usr/local/lib/python3.10/dist-packages/pymysql/connections.py", line 563, in query
    self._affected_rows = self._read_query_result(unbuffered=unbuffered)
  File "/usr/local/lib/python3.10/dist-packages/pymysql/connections.py", line 825, in _read_query_result
    result.read()
  File "/usr/local/lib/python3.10/dist-packages/pymysql/connections.py", line 1199, in read
    first_packet = self.connection._read_packet()
  File "/usr/local/lib/python3.10/dist-packages/pymysql/connections.py", line 775, in _read_packet
    packet.raise_for_error()
  File "/usr/local/lib/python3.10/dist-packages/pymysql/protocol.py", line 219, in raise_for_error
    err.raise_mysql_exception(self._data)
  File "/usr/local/lib/python3.10/dist-packages/pymysql/err.py", line 150, in raise_mysql_exception
    raise errorclass(errno, errval)
pymysql.err.OperationalError: (1292, "Truncated incorrect DOUBLE value: '19903236281aaa'")
2024-08-24 19:19:26|ERROR|app.py:43|(1292, "Truncated incorrect DOUBLE value: '19903236281a'")
Traceback (most recent call last):
  File "app.py", line 40, in wrapper
    return func(*args,**kwargs)
  File "app.py", line 102, in POST
    result = Account.handleLogin(userId, session)
  File "/home/weihong/backendFrame/webpy/./Account.py", line 143, in handleLogin
    DBManage.updateLastLoginTime(userId,now)
  File "/home/weihong/backendFrame/webpy/./DBManage.py", line 25, in updateLastLoginTime
    Config.gdb.update(
  File "/usr/local/lib/python3.10/dist-packages/web/db.py", line 1145, in update
    self._db_execute(db_cursor, query)
  File "/usr/local/lib/python3.10/dist-packages/web/db.py", line 764, in _db_execute
    out = cur.execute(query, params)
  File "/usr/local/lib/python3.10/dist-packages/pymysql/cursors.py", line 153, in execute
    result = self._query(query)
  File "/usr/local/lib/python3.10/dist-packages/pymysql/cursors.py", line 322, in _query
    conn.query(q)
  File "/usr/local/lib/python3.10/dist-packages/pymysql/connections.py", line 563, in query
    self._affected_rows = self._read_query_result(unbuffered=unbuffered)
  File "/usr/local/lib/python3.10/dist-packages/pymysql/connections.py", line 825, in _read_query_result
    result.read()
  File "/usr/local/lib/python3.10/dist-packages/pymysql/connections.py", line 1199, in read
    first_packet = self.connection._read_packet()
  File "/usr/local/lib/python3.10/dist-packages/pymysql/connections.py", line 775, in _read_packet
    packet.raise_for_error()
  File "/usr/local/lib/python3.10/dist-packages/pymysql/protocol.py", line 219, in raise_for_error
    err.raise_mysql_exception(self._data)
  File "/usr/local/lib/python3.10/dist-packages/pymysql/err.py", line 150, in raise_mysql_exception
    raise errorclass(errno, errval)
pymysql.err.OperationalError: (1292, "Truncated incorrect DOUBLE value: '19903236281a'")
2024-08-24 19:20:27|ERROR|app.py:43|(1292, "Truncated incorrect DOUBLE value: '19903236281a'")
Traceback (most recent call last):
  File "app.py", line 40, in wrapper
    return func(*args,**kwargs)
  File "app.py", line 102, in POST
    result = Account.handleLogin(userId, session)
  File "/home/weihong/backendFrame/webpy/./Account.py", line 143, in handleLogin
    DBManage.updateLastLoginTime(userId,now)
  File "/home/weihong/backendFrame/webpy/./DBManage.py", line 25, in updateLastLoginTime
    Config.gdb.update(
  File "/usr/local/lib/python3.10/dist-packages/web/db.py", line 1145, in update
    self._db_execute(db_cursor, query)
  File "/usr/local/lib/python3.10/dist-packages/web/db.py", line 764, in _db_execute
    out = cur.execute(query, params)
  File "/usr/local/lib/python3.10/dist-packages/pymysql/cursors.py", line 153, in execute
    result = self._query(query)
  File "/usr/local/lib/python3.10/dist-packages/pymysql/cursors.py", line 322, in _query
    conn.query(q)
  File "/usr/local/lib/python3.10/dist-packages/pymysql/connections.py", line 563, in query
    self._affected_rows = self._read_query_result(unbuffered=unbuffered)
  File "/usr/local/lib/python3.10/dist-packages/pymysql/connections.py", line 825, in _read_query_result
    result.read()
  File "/usr/local/lib/python3.10/dist-packages/pymysql/connections.py", line 1199, in read
    first_packet = self.connection._read_packet()
  File "/usr/local/lib/python3.10/dist-packages/pymysql/connections.py", line 775, in _read_packet
    packet.raise_for_error()
  File "/usr/local/lib/python3.10/dist-packages/pymysql/protocol.py", line 219, in raise_for_error
    err.raise_mysql_exception(self._data)
  File "/usr/local/lib/python3.10/dist-packages/pymysql/err.py", line 150, in raise_mysql_exception
    raise errorclass(errno, errval)
pymysql.err.OperationalError: (1292, "Truncated incorrect DOUBLE value: '19903236281a'")
2024-08-24 19:23:18|ERROR|app.py:43|(1292, "Truncated incorrect DOUBLE value: '19903236281aa'")
Traceback (most recent call last):
  File "app.py", line 40, in wrapper
    return func(*args,**kwargs)
  File "app.py", line 102, in POST
    result = Account.handleLogin(userId, session)
  File "/home/weihong/backendFrame/webpy/./Account.py", line 143, in handleLogin
    DBManage.updateLastLoginTime(userId,now)
  File "/home/weihong/backendFrame/webpy/./DBManage.py", line 25, in updateLastLoginTime
    Config.gdb.update(
  File "/usr/local/lib/python3.10/dist-packages/web/db.py", line 1145, in update
    self._db_execute(db_cursor, query)
  File "/usr/local/lib/python3.10/dist-packages/web/db.py", line 764, in _db_execute
    out = cur.execute(query, params)
  File "/usr/local/lib/python3.10/dist-packages/pymysql/cursors.py", line 153, in execute
    result = self._query(query)
  File "/usr/local/lib/python3.10/dist-packages/pymysql/cursors.py", line 322, in _query
    conn.query(q)
  File "/usr/local/lib/python3.10/dist-packages/pymysql/connections.py", line 563, in query
    self._affected_rows = self._read_query_result(unbuffered=unbuffered)
  File "/usr/local/lib/python3.10/dist-packages/pymysql/connections.py", line 825, in _read_query_result
    result.read()
  File "/usr/local/lib/python3.10/dist-packages/pymysql/connections.py", line 1199, in read
    first_packet = self.connection._read_packet()
  File "/usr/local/lib/python3.10/dist-packages/pymysql/connections.py", line 775, in _read_packet
    packet.raise_for_error()
  File "/usr/local/lib/python3.10/dist-packages/pymysql/protocol.py", line 219, in raise_for_error
    err.raise_mysql_exception(self._data)
  File "/usr/local/lib/python3.10/dist-packages/pymysql/err.py", line 150, in raise_mysql_exception
    raise errorclass(errno, errval)
pymysql.err.OperationalError: (1292, "Truncated incorrect DOUBLE value: '19903236281aa'")
2024-08-24 19:23:55|ERROR|app.py:43|(1292, "Truncated incorrect DOUBLE value: '19903236281a'")
Traceback (most recent call last):
  File "app.py", line 40, in wrapper
    return func(*args,**kwargs)
  File "app.py", line 102, in POST
    result = Account.handleLogin(userId, session)
  File "/home/weihong/backendFrame/webpy/./Account.py", line 143, in handleLogin
    DBManage.updateLastLoginTime(userId,now)
  File "/home/weihong/backendFrame/webpy/./DBManage.py", line 25, in updateLastLoginTime
    Config.gdb.update(
  File "/usr/local/lib/python3.10/dist-packages/web/db.py", line 1145, in update
    self._db_execute(db_cursor, query)
  File "/usr/local/lib/python3.10/dist-packages/web/db.py", line 764, in _db_execute
    out = cur.execute(query, params)
  File "/usr/local/lib/python3.10/dist-packages/pymysql/cursors.py", line 153, in execute
    result = self._query(query)
  File "/usr/local/lib/python3.10/dist-packages/pymysql/cursors.py", line 322, in _query
    conn.query(q)
  File "/usr/local/lib/python3.10/dist-packages/pymysql/connections.py", line 563, in query
    self._affected_rows = self._read_query_result(unbuffered=unbuffered)
  File "/usr/local/lib/python3.10/dist-packages/pymysql/connections.py", line 825, in _read_query_result
    result.read()
  File "/usr/local/lib/python3.10/dist-packages/pymysql/connections.py", line 1199, in read
    first_packet = self.connection._read_packet()
  File "/usr/local/lib/python3.10/dist-packages/pymysql/connections.py", line 775, in _read_packet
    packet.raise_for_error()
  File "/usr/local/lib/python3.10/dist-packages/pymysql/protocol.py", line 219, in raise_for_error
    err.raise_mysql_exception(self._data)
  File "/usr/local/lib/python3.10/dist-packages/pymysql/err.py", line 150, in raise_mysql_exception
    raise errorclass(errno, errval)
pymysql.err.OperationalError: (1292, "Truncated incorrect DOUBLE value: '19903236281a'")
2024-08-24 19:30:14|ERROR|app.py:43|(1292, "Truncated incorrect DOUBLE value: '19903236281a'")
Traceback (most recent call last):
  File "app.py", line 40, in wrapper
    return func(*args,**kwargs)
  File "app.py", line 102, in POST
    result = Account.handleLogin(userId, session)
  File "/home/weihong/backendFrame/webpy/./Account.py", line 143, in handleLogin
    DBManage.updateLastLoginTime(userId,now)
  File "/home/weihong/backendFrame/webpy/./DBManage.py", line 25, in updateLastLoginTime
    Config.gdb.update(
  File "/usr/local/lib/python3.10/dist-packages/web/db.py", line 1145, in update
    self._db_execute(db_cursor, query)
  File "/usr/local/lib/python3.10/dist-packages/web/db.py", line 764, in _db_execute
    out = cur.execute(query, params)
  File "/usr/local/lib/python3.10/dist-packages/pymysql/cursors.py", line 153, in execute
    result = self._query(query)
  File "/usr/local/lib/python3.10/dist-packages/pymysql/cursors.py", line 322, in _query
    conn.query(q)
  File "/usr/local/lib/python3.10/dist-packages/pymysql/connections.py", line 563, in query
    self._affected_rows = self._read_query_result(unbuffered=unbuffered)
  File "/usr/local/lib/python3.10/dist-packages/pymysql/connections.py", line 825, in _read_query_result
    result.read()
  File "/usr/local/lib/python3.10/dist-packages/pymysql/connections.py", line 1199, in read
    first_packet = self.connection._read_packet()
  File "/usr/local/lib/python3.10/dist-packages/pymysql/connections.py", line 775, in _read_packet
    packet.raise_for_error()
  File "/usr/local/lib/python3.10/dist-packages/pymysql/protocol.py", line 219, in raise_for_error
    err.raise_mysql_exception(self._data)
  File "/usr/local/lib/python3.10/dist-packages/pymysql/err.py", line 150, in raise_mysql_exception
    raise errorclass(errno, errval)
pymysql.err.OperationalError: (1292, "Truncated incorrect DOUBLE value: '19903236281a'")
2024-08-24 19:32:16|ERROR|app.py:43|(1292, "Truncated incorrect DOUBLE value: '19903236281a'")
Traceback (most recent call last):
  File "app.py", line 40, in wrapper
    return func(*args,**kwargs)
  File "app.py", line 102, in POST
    result = Account.handleLogin(userId, session)
  File "/home/weihong/backendFrame/webpy/./Account.py", line 143, in handleLogin
    DBManage.updateLastLoginTime(userId,now)
  File "/home/weihong/backendFrame/webpy/./DBManage.py", line 25, in updateLastLoginTime
    Config.gdb.update(
  File "/usr/local/lib/python3.10/dist-packages/web/db.py", line 1145, in update
    self._db_execute(db_cursor, query)
  File "/usr/local/lib/python3.10/dist-packages/web/db.py", line 764, in _db_execute
    out = cur.execute(query, params)
  File "/usr/local/lib/python3.10/dist-packages/pymysql/cursors.py", line 153, in execute
    result = self._query(query)
  File "/usr/local/lib/python3.10/dist-packages/pymysql/cursors.py", line 322, in _query
    conn.query(q)
  File "/usr/local/lib/python3.10/dist-packages/pymysql/connections.py", line 563, in query
    self._affected_rows = self._read_query_result(unbuffered=unbuffered)
  File "/usr/local/lib/python3.10/dist-packages/pymysql/connections.py", line 825, in _read_query_result
    result.read()
  File "/usr/local/lib/python3.10/dist-packages/pymysql/connections.py", line 1199, in read
    first_packet = self.connection._read_packet()
  File "/usr/local/lib/python3.10/dist-packages/pymysql/connections.py", line 775, in _read_packet
    packet.raise_for_error()
  File "/usr/local/lib/python3.10/dist-packages/pymysql/protocol.py", line 219, in raise_for_error
    err.raise_mysql_exception(self._data)
  File "/usr/local/lib/python3.10/dist-packages/pymysql/err.py", line 150, in raise_mysql_exception
    raise errorclass(errno, errval)
pymysql.err.OperationalError: (1292, "Truncated incorrect DOUBLE value: '19903236281a'")
2024-08-24 19:34:32|ERROR|app.py:43|(1292, "Truncated incorrect DOUBLE value: '19903236281a'")
Traceback (most recent call last):
  File "app.py", line 40, in wrapper
    return func(*args,**kwargs)
  File "app.py", line 102, in POST
    result = Account.handleLogin(userId, session)
  File "/home/weihong/backendFrame/webpy/./Account.py", line 143, in handleLogin
    DBManage.updateLastLoginTime(userId,now)
  File "/home/weihong/backendFrame/webpy/./DBManage.py", line 25, in updateLastLoginTime
    Config.gdb.update(
  File "/usr/local/lib/python3.10/dist-packages/web/db.py", line 1145, in update
    self._db_execute(db_cursor, query)
  File "/usr/local/lib/python3.10/dist-packages/web/db.py", line 764, in _db_execute
    out = cur.execute(query, params)
  File "/usr/local/lib/python3.10/dist-packages/pymysql/cursors.py", line 153, in execute
    result = self._query(query)
  File "/usr/local/lib/python3.10/dist-packages/pymysql/cursors.py", line 322, in _query
    conn.query(q)
  File "/usr/local/lib/python3.10/dist-packages/pymysql/connections.py", line 563, in query
    self._affected_rows = self._read_query_result(unbuffered=unbuffered)
  File "/usr/local/lib/python3.10/dist-packages/pymysql/connections.py", line 825, in _read_query_result
    result.read()
  File "/usr/local/lib/python3.10/dist-packages/pymysql/connections.py", line 1199, in read
    first_packet = self.connection._read_packet()
  File "/usr/local/lib/python3.10/dist-packages/pymysql/connections.py", line 775, in _read_packet
    packet.raise_for_error()
  File "/usr/local/lib/python3.10/dist-packages/pymysql/protocol.py", line 219, in raise_for_error
    err.raise_mysql_exception(self._data)
  File "/usr/local/lib/python3.10/dist-packages/pymysql/err.py", line 150, in raise_mysql_exception
    raise errorclass(errno, errval)
pymysql.err.OperationalError: (1292, "Truncated incorrect DOUBLE value: '19903236281a'")
2024-08-24 20:05:07|ERROR|app.py:43|(1292, "Truncated incorrect DOUBLE value: '19903236281a'")
Traceback (most recent call last):
  File "app.py", line 40, in wrapper
    return func(*args,**kwargs)
  File "app.py", line 102, in POST
    result = Account.handleLogin(userId, session)
  File "/home/weihong/backendFrame/webpy/./Account.py", line 144, in handleLogin
    DBManage.updateLastLoginTime(userId,now)
  File "/home/weihong/backendFrame/webpy/./DBManage.py", line 25, in updateLastLoginTime
    Config.gdb.update(
  File "/usr/local/lib/python3.10/dist-packages/web/db.py", line 1145, in update
    self._db_execute(db_cursor, query)
  File "/usr/local/lib/python3.10/dist-packages/web/db.py", line 764, in _db_execute
    out = cur.execute(query, params)
  File "/usr/local/lib/python3.10/dist-packages/pymysql/cursors.py", line 153, in execute
    result = self._query(query)
  File "/usr/local/lib/python3.10/dist-packages/pymysql/cursors.py", line 322, in _query
    conn.query(q)
  File "/usr/local/lib/python3.10/dist-packages/pymysql/connections.py", line 563, in query
    self._affected_rows = self._read_query_result(unbuffered=unbuffered)
  File "/usr/local/lib/python3.10/dist-packages/pymysql/connections.py", line 825, in _read_query_result
    result.read()
  File "/usr/local/lib/python3.10/dist-packages/pymysql/connections.py", line 1199, in read
    first_packet = self.connection._read_packet()
  File "/usr/local/lib/python3.10/dist-packages/pymysql/connections.py", line 775, in _read_packet
    packet.raise_for_error()
  File "/usr/local/lib/python3.10/dist-packages/pymysql/protocol.py", line 219, in raise_for_error
    err.raise_mysql_exception(self._data)
  File "/usr/local/lib/python3.10/dist-packages/pymysql/err.py", line 150, in raise_mysql_exception
    raise errorclass(errno, errval)
pymysql.err.OperationalError: (1292, "Truncated incorrect DOUBLE value: '19903236281a'")
2024-08-24 20:06:13|ERROR|app.py:43|0
Traceback (most recent call last):
  File "/usr/local/lib/python3.10/dist-packages/web/db.py", line 538, in __getitem__
    return next(self)
  File "/usr/local/lib/python3.10/dist-packages/web/db.py", line 510, in __next__
    raise StopIteration()
StopIteration

During handling of the above exception, another exception occurred:

Traceback (most recent call last):
  File "app.py", line 40, in wrapper
    return func(*args,**kwargs)
  File "app.py", line 96, in POST
    result = Account.verifyAccount(userId,password)
  File "/home/weihong/backendFrame/webpy/./Account.py", line 122, in verifyAccount
    print(result[0])
  File "/usr/local/lib/python3.10/dist-packages/web/db.py", line 540, in __getitem__
    raise IndexError(str(i))
IndexError: 0
2024-08-24 20:06:25|ERROR|app.py:43|already passed 0
Traceback (most recent call last):
  File "app.py", line 40, in wrapper
    return func(*args,**kwargs)
  File "app.py", line 96, in POST
    result = Account.verifyAccount(userId,password)
  File "/home/weihong/backendFrame/webpy/./Account.py", line 127, in verifyAccount
    if result[0]['password'] != password:
  File "/usr/local/lib/python3.10/dist-packages/web/db.py", line 531, in __getitem__
    raise IndexError("already passed " + str(i))
IndexError: already passed 0
2024-08-24 20:06:53|ERROR|app.py:43|already passed 0
Traceback (most recent call last):
  File "app.py", line 40, in wrapper
    return func(*args,**kwargs)
  File "app.py", line 96, in POST
    result = Account.verifyAccount(userId,password)
  File "/home/weihong/backendFrame/webpy/./Account.py", line 127, in verifyAccount
    if result[0]['password'] != password:
  File "/usr/local/lib/python3.10/dist-packages/web/db.py", line 531, in __getitem__
    raise IndexError("already passed " + str(i))
IndexError: already passed 0
2024-08-24 20:07:20|ERROR|app.py:43|already passed 0
Traceback (most recent call last):
  File "app.py", line 40, in wrapper
    return func(*args,**kwargs)
  File "app.py", line 96, in POST
    result = Account.verifyAccount(userId,password)
  File "/home/weihong/backendFrame/webpy/./Account.py", line 127, in verifyAccount
    if result[0]['password'] != password:
  File "/usr/local/lib/python3.10/dist-packages/web/db.py", line 531, in __getitem__
    raise IndexError("already passed " + str(i))
IndexError: already passed 0
2024-08-24 20:07:32|ERROR|app.py:43|0
Traceback (most recent call last):
  File "/usr/local/lib/python3.10/dist-packages/web/db.py", line 538, in __getitem__
    return next(self)
  File "/usr/local/lib/python3.10/dist-packages/web/db.py", line 510, in __next__
    raise StopIteration()
StopIteration

During handling of the above exception, another exception occurred:

Traceback (most recent call last):
  File "app.py", line 40, in wrapper
    return func(*args,**kwargs)
  File "app.py", line 96, in POST
    result = Account.verifyAccount(userId,password)
  File "/home/weihong/backendFrame/webpy/./Account.py", line 122, in verifyAccount
    print(result[0])
  File "/usr/local/lib/python3.10/dist-packages/web/db.py", line 540, in __getitem__
    raise IndexError(str(i))
IndexError: 0
2024-08-24 20:07:35|ERROR|app.py:43|0
Traceback (most recent call last):
  File "/usr/local/lib/python3.10/dist-packages/web/db.py", line 538, in __getitem__
    return next(self)
  File "/usr/local/lib/python3.10/dist-packages/web/db.py", line 510, in __next__
    raise StopIteration()
StopIteration

During handling of the above exception, another exception occurred:

Traceback (most recent call last):
  File "app.py", line 40, in wrapper
    return func(*args,**kwargs)
  File "app.py", line 96, in POST
    result = Account.verifyAccount(userId,password)
  File "/home/weihong/backendFrame/webpy/./Account.py", line 122, in verifyAccount
    print(result[0])
  File "/usr/local/lib/python3.10/dist-packages/web/db.py", line 540, in __getitem__
    raise IndexError(str(i))
IndexError: 0
2024-08-24 20:09:54|ERROR|app.py:43|already passed 0
Traceback (most recent call last):
  File "app.py", line 40, in wrapper
    return func(*args,**kwargs)
  File "app.py", line 96, in POST
    result = Account.verifyAccount(userId,password)
  File "/home/weihong/backendFrame/webpy/./Account.py", line 128, in verifyAccount
    print(result[0]['password'])
  File "/usr/local/lib/python3.10/dist-packages/web/db.py", line 531, in __getitem__
    raise IndexError("already passed " + str(i))
IndexError: already passed 0
2024-08-24 20:14:25|ERROR|app.py:43|already passed 0
Traceback (most recent call last):
  File "app.py", line 40, in wrapper
    return func(*args,**kwargs)
  File "app.py", line 96, in POST
    result = Account.verifyAccount(userId,password)
  File "/home/weihong/backendFrame/webpy/./Account.py", line 127, in verifyAccount
    if result[0]['password'] != password:
  File "/usr/local/lib/python3.10/dist-packages/web/db.py", line 531, in __getitem__
    raise IndexError("already passed " + str(i))
IndexError: already passed 0
2024-08-24 20:14:43|ERROR|app.py:43|already passed 0
Traceback (most recent call last):
  File "app.py", line 40, in wrapper
    return func(*args,**kwargs)
  File "app.py", line 96, in POST
    result = Account.verifyAccount(userId,password)
  File "/home/weihong/backendFrame/webpy/./Account.py", line 127, in verifyAccount
    if result[0]['password'] != password:
  File "/usr/local/lib/python3.10/dist-packages/web/db.py", line 531, in __getitem__
    raise IndexError("already passed " + str(i))
IndexError: already passed 0
2024-08-24 20:16:06|ERROR|app.py:43|already passed 0
Traceback (most recent call last):
  File "app.py", line 40, in wrapper
    return func(*args,**kwargs)
  File "app.py", line 96, in POST
    result = Account.verifyAccount(userId,password)
  File "/home/weihong/backendFrame/webpy/./Account.py", line 127, in verifyAccount
    if result[0]['password'] != password:
  File "/usr/local/lib/python3.10/dist-packages/web/db.py", line 531, in __getitem__
    raise IndexError("already passed " + str(i))
IndexError: already passed 0
2024-08-24 20:16:50|ERROR|app.py:43|already passed 0
Traceback (most recent call last):
  File "app.py", line 40, in wrapper
    return func(*args,**kwargs)
  File "app.py", line 96, in POST
    result = Account.verifyAccount(userId,password)
  File "/home/weihong/backendFrame/webpy/./Account.py", line 127, in verifyAccount
    if result[0]['password'] != password:
  File "/usr/local/lib/python3.10/dist-packages/web/db.py", line 531, in __getitem__
    raise IndexError("already passed " + str(i))
IndexError: already passed 0
2024-08-24 20:18:13|ERROR|app.py:43|already passed 0
Traceback (most recent call last):
  File "app.py", line 40, in wrapper
    return func(*args,**kwargs)
  File "app.py", line 96, in POST
    result = Account.verifyAccount(userId,password)
  File "/home/weihong/backendFrame/webpy/./Account.py", line 127, in verifyAccount
    print(result[0]['password'])
  File "/usr/local/lib/python3.10/dist-packages/web/db.py", line 531, in __getitem__
    raise IndexError("already passed " + str(i))
IndexError: already passed 0
2024-08-24 20:20:08|ERROR|app.py:43|already passed 0
Traceback (most recent call last):
  File "app.py", line 40, in wrapper
    return func(*args,**kwargs)
  File "app.py", line 96, in POST
    result = Account.verifyAccount(userId,password)
  File "/home/weihong/backendFrame/webpy/./Account.py", line 127, in verifyAccount
    if result[0]['password'] != password:
  File "/usr/local/lib/python3.10/dist-packages/web/db.py", line 531, in __getitem__
    raise IndexError("already passed " + str(i))
IndexError: already passed 0
2024-08-24 20:30:31|ERROR|app.py:43|0
Traceback (most recent call last):
  File "app.py", line 40, in wrapper
    return func(*args,**kwargs)
  File "app.py", line 96, in POST
    result = Account.verifyAccount(userId,password)
  File "/home/weihong/backendFrame/webpy/./Account.py", line 128, in verifyAccount
    if result[0]['password'] != password:
KeyError: 0
2024-08-24 20:32:24|ERROR|app.py:43|'<' not supported between instances of 'str' and 'int'
Traceback (most recent call last):
  File "app.py", line 40, in wrapper
    return func(*args,**kwargs)
  File "app.py", line 96, in POST
    result = Account.verifyAccount(userId,password)
  File "/home/weihong/backendFrame/webpy/./Account.py", line 134, in verifyAccount
    if result['status'] == Config.USER_STATUS_FRERZE:
  File "/usr/local/lib/python3.10/dist-packages/web/db.py", line 530, in __getitem__
    if i < self._index:
TypeError: '<' not supported between instances of 'str' and 'int'
2024-08-24 20:33:45|ERROR|app.py:43|(1292, "Truncated incorrect DOUBLE value: '19903236281a'")
Traceback (most recent call last):
  File "app.py", line 40, in wrapper
    return func(*args,**kwargs)
  File "app.py", line 102, in POST
    result = Account.handleLogin(userId, session)
  File "/home/weihong/backendFrame/webpy/./Account.py", line 147, in handleLogin
    DBManage.updateLastLoginTime(userId,now)
  File "/home/weihong/backendFrame/webpy/./DBManage.py", line 25, in updateLastLoginTime
    Config.gdb.update(
  File "/usr/local/lib/python3.10/dist-packages/web/db.py", line 1145, in update
    self._db_execute(db_cursor, query)
  File "/usr/local/lib/python3.10/dist-packages/web/db.py", line 764, in _db_execute
    out = cur.execute(query, params)
  File "/usr/local/lib/python3.10/dist-packages/pymysql/cursors.py", line 153, in execute
    result = self._query(query)
  File "/usr/local/lib/python3.10/dist-packages/pymysql/cursors.py", line 322, in _query
    conn.query(q)
  File "/usr/local/lib/python3.10/dist-packages/pymysql/connections.py", line 563, in query
    self._affected_rows = self._read_query_result(unbuffered=unbuffered)
  File "/usr/local/lib/python3.10/dist-packages/pymysql/connections.py", line 825, in _read_query_result
    result.read()
  File "/usr/local/lib/python3.10/dist-packages/pymysql/connections.py", line 1199, in read
    first_packet = self.connection._read_packet()
  File "/usr/local/lib/python3.10/dist-packages/pymysql/connections.py", line 775, in _read_packet
    packet.raise_for_error()
  File "/usr/local/lib/python3.10/dist-packages/pymysql/protocol.py", line 219, in raise_for_error
    err.raise_mysql_exception(self._data)
  File "/usr/local/lib/python3.10/dist-packages/pymysql/err.py", line 150, in raise_mysql_exception
    raise errorclass(errno, errval)
pymysql.err.OperationalError: (1292, "Truncated incorrect DOUBLE value: '19903236281a'")
2024-08-24 20:34:03|ERROR|app.py:43|0
Traceback (most recent call last):
  File "/usr/local/lib/python3.10/dist-packages/web/db.py", line 538, in __getitem__
    return next(self)
  File "/usr/local/lib/python3.10/dist-packages/web/db.py", line 510, in __next__
    raise StopIteration()
StopIteration

During handling of the above exception, another exception occurred:

Traceback (most recent call last):
  File "app.py", line 40, in wrapper
    return func(*args,**kwargs)
  File "app.py", line 96, in POST
    result = Account.verifyAccount(userId,password)
  File "/home/weihong/backendFrame/webpy/./Account.py", line 122, in verifyAccount
    sql_password = result[0]['password']
  File "/usr/local/lib/python3.10/dist-packages/web/db.py", line 540, in __getitem__
    raise IndexError(str(i))
IndexError: 0
2024-08-24 20:35:21|ERROR|app.py:43|(1292, "Truncated incorrect DOUBLE value: '19903236281a'")
Traceback (most recent call last):
  File "app.py", line 40, in wrapper
    return func(*args,**kwargs)
  File "app.py", line 102, in POST
    result = Account.handleLogin(userId, session)
  File "/home/weihong/backendFrame/webpy/./Account.py", line 147, in handleLogin
    DBManage.updateLastLoginTime(userId,now)
  File "/home/weihong/backendFrame/webpy/./DBManage.py", line 25, in updateLastLoginTime
    Config.gdb.update(
  File "/usr/local/lib/python3.10/dist-packages/web/db.py", line 1145, in update
    self._db_execute(db_cursor, query)
  File "/usr/local/lib/python3.10/dist-packages/web/db.py", line 764, in _db_execute
    out = cur.execute(query, params)
  File "/usr/local/lib/python3.10/dist-packages/pymysql/cursors.py", line 153, in execute
    result = self._query(query)
  File "/usr/local/lib/python3.10/dist-packages/pymysql/cursors.py", line 322, in _query
    conn.query(q)
  File "/usr/local/lib/python3.10/dist-packages/pymysql/connections.py", line 563, in query
    self._affected_rows = self._read_query_result(unbuffered=unbuffered)
  File "/usr/local/lib/python3.10/dist-packages/pymysql/connections.py", line 825, in _read_query_result
    result.read()
  File "/usr/local/lib/python3.10/dist-packages/pymysql/connections.py", line 1199, in read
    first_packet = self.connection._read_packet()
  File "/usr/local/lib/python3.10/dist-packages/pymysql/connections.py", line 775, in _read_packet
    packet.raise_for_error()
  File "/usr/local/lib/python3.10/dist-packages/pymysql/protocol.py", line 219, in raise_for_error
    err.raise_mysql_exception(self._data)
  File "/usr/local/lib/python3.10/dist-packages/pymysql/err.py", line 150, in raise_mysql_exception
    raise errorclass(errno, errval)
pymysql.err.OperationalError: (1292, "Truncated incorrect DOUBLE value: '19903236281a'")
2024-08-24 20:42:59|ERROR|app.py:43|(1292, "Truncated incorrect DOUBLE value: '19903236281a'")
Traceback (most recent call last):
  File "app.py", line 40, in wrapper
    return func(*args,**kwargs)
  File "app.py", line 102, in POST
    result = Account.handleLogin(userId, session)
  File "/home/weihong/backendFrame/webpy/./Account.py", line 149, in handleLogin
    DBManage.updateLastLoginTime(userId,now)
  File "/home/weihong/backendFrame/webpy/./DBManage.py", line 25, in updateLastLoginTime
    Config.gdb.update(
  File "/usr/local/lib/python3.10/dist-packages/web/db.py", line 1145, in update
    self._db_execute(db_cursor, query)
  File "/usr/local/lib/python3.10/dist-packages/web/db.py", line 764, in _db_execute
    out = cur.execute(query, params)
  File "/usr/local/lib/python3.10/dist-packages/pymysql/cursors.py", line 153, in execute
    result = self._query(query)
  File "/usr/local/lib/python3.10/dist-packages/pymysql/cursors.py", line 322, in _query
    conn.query(q)
  File "/usr/local/lib/python3.10/dist-packages/pymysql/connections.py", line 563, in query
    self._affected_rows = self._read_query_result(unbuffered=unbuffered)
  File "/usr/local/lib/python3.10/dist-packages/pymysql/connections.py", line 825, in _read_query_result
    result.read()
  File "/usr/local/lib/python3.10/dist-packages/pymysql/connections.py", line 1199, in read
    first_packet = self.connection._read_packet()
  File "/usr/local/lib/python3.10/dist-packages/pymysql/connections.py", line 775, in _read_packet
    packet.raise_for_error()
  File "/usr/local/lib/python3.10/dist-packages/pymysql/protocol.py", line 219, in raise_for_error
    err.raise_mysql_exception(self._data)
  File "/usr/local/lib/python3.10/dist-packages/pymysql/err.py", line 150, in raise_mysql_exception
    raise errorclass(errno, errval)
pymysql.err.OperationalError: (1292, "Truncated incorrect DOUBLE value: '19903236281a'")
2024-08-24 20:47:54|ERROR|app.py:43|(1292, "Truncated incorrect DOUBLE value: '19903236281a'")
Traceback (most recent call last):
  File "app.py", line 40, in wrapper
    return func(*args,**kwargs)
  File "app.py", line 102, in POST
    result = Account.handleLogin(userId, session)
  File "/home/weihong/backendFrame/webpy/./Account.py", line 149, in handleLogin
    DBManage.updateLastLoginTime(userId,now)
  File "/home/weihong/backendFrame/webpy/./DBManage.py", line 25, in updateLastLoginTime
    Config.gdb.update(
  File "/usr/local/lib/python3.10/dist-packages/web/db.py", line 1145, in update
    self._db_execute(db_cursor, query)
  File "/usr/local/lib/python3.10/dist-packages/web/db.py", line 764, in _db_execute
    out = cur.execute(query, params)
  File "/usr/local/lib/python3.10/dist-packages/pymysql/cursors.py", line 153, in execute
    result = self._query(query)
  File "/usr/local/lib/python3.10/dist-packages/pymysql/cursors.py", line 322, in _query
    conn.query(q)
  File "/usr/local/lib/python3.10/dist-packages/pymysql/connections.py", line 563, in query
    self._affected_rows = self._read_query_result(unbuffered=unbuffered)
  File "/usr/local/lib/python3.10/dist-packages/pymysql/connections.py", line 825, in _read_query_result
    result.read()
  File "/usr/local/lib/python3.10/dist-packages/pymysql/connections.py", line 1199, in read
    first_packet = self.connection._read_packet()
  File "/usr/local/lib/python3.10/dist-packages/pymysql/connections.py", line 775, in _read_packet
    packet.raise_for_error()
  File "/usr/local/lib/python3.10/dist-packages/pymysql/protocol.py", line 219, in raise_for_error
    err.raise_mysql_exception(self._data)
  File "/usr/local/lib/python3.10/dist-packages/pymysql/err.py", line 150, in raise_mysql_exception
    raise errorclass(errno, errval)
pymysql.err.OperationalError: (1292, "Truncated incorrect DOUBLE value: '19903236281a'")
2024-08-24 21:16:02|ERROR|app.py:43|(1054, "Unknown column '19903236281a' in 'where clause'")
Traceback (most recent call last):
  File "app.py", line 40, in wrapper
    return func(*args,**kwargs)
  File "app.py", line 96, in POST
    result = Account.verifyAccount(userId,password)
  File "/home/weihong/backendFrame/webpy/./Account.py", line 126, in verifyAccount
    result = Config.gdb.query("select password from user where userid = 19903236281a")
  File "/usr/local/lib/python3.10/dist-packages/web/db.py", line 837, in query
    self._db_execute(db_cursor, sql_query)
  File "/usr/local/lib/python3.10/dist-packages/web/db.py", line 764, in _db_execute
    out = cur.execute(query, params)
  File "/usr/local/lib/python3.10/dist-packages/pymysql/cursors.py", line 153, in execute
    result = self._query(query)
  File "/usr/local/lib/python3.10/dist-packages/pymysql/cursors.py", line 322, in _query
    conn.query(q)
  File "/usr/local/lib/python3.10/dist-packages/pymysql/connections.py", line 563, in query
    self._affected_rows = self._read_query_result(unbuffered=unbuffered)
  File "/usr/local/lib/python3.10/dist-packages/pymysql/connections.py", line 825, in _read_query_result
    result.read()
  File "/usr/local/lib/python3.10/dist-packages/pymysql/connections.py", line 1199, in read
    first_packet = self.connection._read_packet()
  File "/usr/local/lib/python3.10/dist-packages/pymysql/connections.py", line 775, in _read_packet
    packet.raise_for_error()
  File "/usr/local/lib/python3.10/dist-packages/pymysql/protocol.py", line 219, in raise_for_error
    err.raise_mysql_exception(self._data)
  File "/usr/local/lib/python3.10/dist-packages/pymysql/err.py", line 150, in raise_mysql_exception
    raise errorclass(errno, errval)
pymysql.err.OperationalError: (1054, "Unknown column '19903236281a' in 'where clause'")
2024-08-24 21:18:52|ERROR|app.py:43|(1054, "Unknown column '19903236281a' in 'where clause'")
Traceback (most recent call last):
  File "app.py", line 40, in wrapper
    return func(*args,**kwargs)
  File "app.py", line 96, in POST
    result = Account.verifyAccount(userId,password)
  File "/home/weihong/backendFrame/webpy/./Account.py", line 126, in verifyAccount
    result = Config.gdb.query("select password from user where userid = {}".format(userId))
  File "/usr/local/lib/python3.10/dist-packages/web/db.py", line 837, in query
    self._db_execute(db_cursor, sql_query)
  File "/usr/local/lib/python3.10/dist-packages/web/db.py", line 764, in _db_execute
    out = cur.execute(query, params)
  File "/usr/local/lib/python3.10/dist-packages/pymysql/cursors.py", line 153, in execute
    result = self._query(query)
  File "/usr/local/lib/python3.10/dist-packages/pymysql/cursors.py", line 322, in _query
    conn.query(q)
  File "/usr/local/lib/python3.10/dist-packages/pymysql/connections.py", line 563, in query
    self._affected_rows = self._read_query_result(unbuffered=unbuffered)
  File "/usr/local/lib/python3.10/dist-packages/pymysql/connections.py", line 825, in _read_query_result
    result.read()
  File "/usr/local/lib/python3.10/dist-packages/pymysql/connections.py", line 1199, in read
    first_packet = self.connection._read_packet()
  File "/usr/local/lib/python3.10/dist-packages/pymysql/connections.py", line 775, in _read_packet
    packet.raise_for_error()
  File "/usr/local/lib/python3.10/dist-packages/pymysql/protocol.py", line 219, in raise_for_error
    err.raise_mysql_exception(self._data)
  File "/usr/local/lib/python3.10/dist-packages/pymysql/err.py", line 150, in raise_mysql_exception
    raise errorclass(errno, errval)
pymysql.err.OperationalError: (1054, "Unknown column '19903236281a' in 'where clause'")
2024-08-24 21:43:29|ERROR|app.py:43|0
Traceback (most recent call last):
  File "/usr/local/lib/python3.10/dist-packages/web/db.py", line 538, in __getitem__
    return next(self)
  File "/usr/local/lib/python3.10/dist-packages/web/db.py", line 510, in __next__
    raise StopIteration()
StopIteration

During handling of the above exception, another exception occurred:

Traceback (most recent call last):
  File "app.py", line 40, in wrapper
    return func(*args,**kwargs)
  File "app.py", line 96, in POST
    result = Account.verifyAccount(userId,password)
  File "/home/weihong/backendFrame/webpy/./Account.py", line 128, in verifyAccount
    sql_result = result[0]
  File "/usr/local/lib/python3.10/dist-packages/web/db.py", line 540, in __getitem__
    raise IndexError(str(i))
IndexError: 0
